Restoring modules from user's fosscuda111, for system: "farnam-rhel7"
Built MedMentions DB
  0%|          | 0/4392 [00:00<?, ?it/s] 46%|████▋     | 2037/4392 [00:00<00:00, 4073.76it/s] 85%|████████▍ | 3715/4392 [00:01<00:00, 3828.11it/s]100%|██████████| 4392/4392 [00:01<00:00, 3633.76it/s]
Built Entity Vocab
  0%|          | 0/4392 [00:00<?, ?it/s]  0%|          | 1/4392 [01:10<85:29:43, 70.09s/it]  2%|▏         | 101/4392 [01:29<58:33:14, 49.12s/it]  9%|▉         | 390/4392 [01:29<38:13:38, 34.39s/it] 15%|█▍        | 655/4392 [01:29<24:59:14, 24.07s/it] 18%|█▊        | 800/4392 [01:40<24:01:04, 24.07s/it] 18%|█▊        | 801/4392 [02:11<16:53:31, 16.93s/it] 23%|██▎       | 1001/4392 [02:24<11:11:06, 11.87s/it] 25%|██▌       | 1101/4392 [02:38<7:38:16,  8.35s/it]  27%|██▋       | 1201/4392 [02:45<5:12:02,  5.87s/it] 34%|███▍      | 1501/4392 [02:59<3:18:34,  4.12s/it] 36%|███▋      | 1601/4392 [03:00<2:14:19,  2.89s/it] 39%|███▊      | 1701/4392 [03:11<1:32:10,  2.06s/it] 41%|████      | 1801/4392 [03:36<1:05:21,  1.51s/it] 46%|████▌     | 2001/4392 [04:01<43:43,  1.10s/it]   48%|████▊     | 2101/4392 [04:04<29:35,  1.29it/s] 52%|█████▏    | 2300/4392 [04:20<27:01,  1.29it/s] 52%|█████▏    | 2301/4392 [04:36<20:36,  1.69it/s] 58%|█████▊    | 2531/4392 [04:36<12:50,  2.41it/s] 59%|█████▉    | 2600/4392 [04:50<12:22,  2.41it/s] 59%|█████▉    | 2601/4392 [04:56<11:08,  2.68it/s] 65%|██████▌   | 2860/4392 [04:56<06:40,  3.83it/s] 66%|██████▌   | 2900/4392 [05:10<06:30,  3.83it/s] 66%|██████▌   | 2901/4392 [05:33<11:20,  2.19it/s] 71%|███████   | 3097/4392 [05:33<06:53,  3.13it/s] 75%|███████▌  | 3300/4392 [05:50<05:49,  3.13it/s] 75%|███████▌  | 3301/4392 [05:58<04:42,  3.86it/s] 82%|████████▏ | 3601/4392 [06:09<02:32,  5.18it/s] 84%|████████▍ | 3700/4392 [06:20<02:13,  5.18it/s] 84%|████████▍ | 3701/4392 [06:35<02:26,  4.70it/s] 87%|████████▋ | 3801/4392 [06:50<01:54,  5.17it/s] 92%|█████████▏| 4052/4392 [06:50<00:46,  7.38it/s] 96%|█████████▌| 4201/4392 [07:02<00:22,  8.40it/s]100%|██████████| 4392/4392 [07:02<00:00, 10.39it/s]
Built Pretraining Dataset
pretraining num steps: 4392
[2021-06-01 02:10:12,604] [INFO] Starting pretraining with the following arguments: {
  "adam_b1": 0.9,
  "adam_b2": 0.999,
  "adam_eps": 1e-06,
  "amp_file": null,
  "batch_size": 1024,
  "bert_model_name": "microsoft/BiomedNLP-PubMedBERT-base-uncased-abstract",
  "cpu": false,
  "dataset_dir": "/home/vs428/project/MedMentions/full/pretraining",
  "entity_emb_size": 256,
  "fix_bert_weights": false,
  "fp16": false,
  "fp16_master_weights": true,
  "fp16_max_loss_scale": 4,
  "fp16_min_loss_scale": 1,
  "fp16_opt_level": "O2",
  "global_step": 0,
  "grad_avg_on_cpu": false,
  "gradient_accumulation_steps": 512,
  "learning_rate": 1e-05,
  "local_rank": -1,
  "log_dir": "runs/fullmedmentions_warmup800",
  "lr_schedule": "warmup_linear",
  "mask_words_in_entity_span": false,
  "masked_entity_prob": 0.15,
  "masked_lm_prob": 0.15,
  "master_addr": "127.0.0.1",
  "master_port": "29502",
  "max_grad_norm": 0.0,
  "model_file": null,
  "node_rank": 0,
  "num_epochs": 20,
  "num_nodes": 1,
  "optimizer_file": null,
  "output_dir": "/home/vs428/project/MedMentions/full/pretraining",
  "parallel": false,
  "random_entity_prob": 0.0,
  "random_word_prob": 0.1,
  "sampling_smoothing": 0.7,
  "save_interval_sec": null,
  "save_interval_steps": null,
  "scheduler_file": null,
  "unmasked_entity_prob": 0.0,
  "unmasked_word_prob": 0.1,
  "warmup_steps": 800,
  "weight_decay": 0.01,
  "whole_word_masking": true
} (run_pretraining@train.py:167)
[2021-06-01 02:10:14,990] [INFO] Model configuration: LukeConfig {
  "architectures": null,
  "attention_probs_dropout_prob": 0.1,
  "bert_model_name": "microsoft/BiomedNLP-PubMedBERT-base-uncased-abstract",
  "bos_token_id": 0,
  "do_sample": false,
  "entity_emb_size": 256,
  "entity_vocab_size": 34727,
  "eos_token_ids": 0,
  "finetuning_task": null,
  "hidden_act": "gelu",
  "hidden_dropout_prob": 0.1,
  "hidden_size": 768,
  "id2label": {
    "0": "LABEL_0",
    "1": "LABEL_1"
  },
  "initializer_range": 0.02,
  "intermediate_size": 3072,
  "is_decoder": false,
  "label2id": {
    "LABEL_0": 0,
    "LABEL_1": 1
  },
  "layer_norm_eps": 1e-12,
  "length_penalty": 1.0,
  "max_length": 20,
  "max_position_embeddings": 512,
  "model_type": "bert",
  "num_attention_heads": 12,
  "num_beams": 1,
  "num_hidden_layers": 12,
  "num_labels": 2,
  "num_return_sequences": 1,
  "output_attentions": false,
  "output_hidden_states": false,
  "output_past": true,
  "pad_token_id": 0,
  "pruned_heads": {},
  "repetition_penalty": 1.0,
  "temperature": 1.0,
  "top_k": 50,
  "top_p": 1.0,
  "torchscript": false,
  "type_vocab_size": 2,
  "use_bfloat16": false,
  "vocab_size": 30522
}
 (run_pretraining@train.py:218)
  0%|          | 0/89 [00:00<?, ?it/s]Process LukePretrainingBatchWorker-1:
Traceback (most recent call last):
  File "/gpfs/ysm/project/rtaylor/vs428/conda_envs/el_env111/lib/python3.6/site-packages/tensorflow_core/python/client/session.py", line 1365, in _do_call
    return fn(*args)
  File "/gpfs/ysm/project/rtaylor/vs428/conda_envs/el_env111/lib/python3.6/site-packages/tensorflow_core/python/client/session.py", line 1350, in _run_fn
    target_list, run_metadata)
  File "/gpfs/ysm/project/rtaylor/vs428/conda_envs/el_env111/lib/python3.6/site-packages/tensorflow_core/python/client/session.py", line 1443, in _call_tf_sessionrun
    run_metadata)
tensorflow.python.framework.errors_impl.DataLossError: corrupted record at 66770955
	 [[{{node IteratorGetNext}}]]

During handling of the above exception, another exception occurred:

Traceback (most recent call last):
  File "/gpfs/ysm/project/rtaylor/vs428/conda_envs/el_env111/lib/python3.6/multiprocessing/process.py", line 258, in _bootstrap
    self.run()
  File "/gpfs/ysm/home/vs428/Documents/luke/luke/pretraining/batch_generator.py", line 126, in run
    for item in self._pretraining_dataset.create_iterator(**self._dataset_kwargs):
  File "/gpfs/ysm/home/vs428/Documents/luke/luke/pretraining/medmentions_dataset.py", line 139, in create_iterator
    obj = sess.run(it)
  File "/gpfs/ysm/project/rtaylor/vs428/conda_envs/el_env111/lib/python3.6/site-packages/tensorflow_core/python/client/session.py", line 956, in run
    run_metadata_ptr)
  File "/gpfs/ysm/project/rtaylor/vs428/conda_envs/el_env111/lib/python3.6/site-packages/tensorflow_core/python/client/session.py", line 1180, in _run
    feed_dict_tensor, options, run_metadata)
  File "/gpfs/ysm/project/rtaylor/vs428/conda_envs/el_env111/lib/python3.6/site-packages/tensorflow_core/python/client/session.py", line 1359, in _do_run
    run_metadata)
  File "/gpfs/ysm/project/rtaylor/vs428/conda_envs/el_env111/lib/python3.6/site-packages/tensorflow_core/python/client/session.py", line 1384, in _do_call
    raise type(e)(node_def, op, message)
tensorflow.python.framework.errors_impl.DataLossError: corrupted record at 66770955
	 [[node IteratorGetNext (defined at /gpfs/ysm/project/rtaylor/vs428/conda_envs/el_env111/lib/python3.6/site-packages/tensorflow_core/python/framework/ops.py:1748) ]]

Original stack trace for 'IteratorGetNext':
  File "cli.py", line 77, in <module>
    cli()
  File "/gpfs/ysm/project/rtaylor/vs428/conda_envs/el_env111/lib/python3.6/site-packages/click/core.py", line 829, in __call__
    return self.main(*args, **kwargs)
  File "/gpfs/ysm/project/rtaylor/vs428/conda_envs/el_env111/lib/python3.6/site-packages/click/core.py", line 782, in main
    rv = self.invoke(ctx)
  File "/gpfs/ysm/project/rtaylor/vs428/conda_envs/el_env111/lib/python3.6/site-packages/click/core.py", line 1259, in invoke
    return _process_result(sub_ctx.command.invoke(sub_ctx))
  File "/gpfs/ysm/project/rtaylor/vs428/conda_envs/el_env111/lib/python3.6/site-packages/click/core.py", line 1066, in invoke
    return ctx.invoke(self.callback, **ctx.params)
  File "/gpfs/ysm/project/rtaylor/vs428/conda_envs/el_env111/lib/python3.6/site-packages/click/core.py", line 610, in invoke
    return callback(*args, **kwargs)
  File "/gpfs/ysm/home/vs428/Documents/luke/luke/pretraining/train.py", line 81, in pretrain
    run_pretraining(Namespace(**kwargs))
  File "/gpfs/ysm/home/vs428/Documents/luke/luke/pretraining/train.py", line 350, in run_pretraining
    for batch in batch_generator.generate_batches():
  File "/gpfs/ysm/home/vs428/Documents/luke/luke/pretraining/batch_generator.py", line 56, in generate_batches
    worker.start()
  File "/gpfs/ysm/project/rtaylor/vs428/conda_envs/el_env111/lib/python3.6/multiprocessing/process.py", line 105, in start
    self._popen = self._Popen(self)
  File "/gpfs/ysm/project/rtaylor/vs428/conda_envs/el_env111/lib/python3.6/multiprocessing/context.py", line 223, in _Popen
    return _default_context.get_context().Process._Popen(process_obj)
  File "/gpfs/ysm/project/rtaylor/vs428/conda_envs/el_env111/lib/python3.6/multiprocessing/context.py", line 277, in _Popen
    return Popen(process_obj)
  File "/gpfs/ysm/project/rtaylor/vs428/conda_envs/el_env111/lib/python3.6/multiprocessing/popen_fork.py", line 19, in __init__
    self._launch(process_obj)
  File "/gpfs/ysm/project/rtaylor/vs428/conda_envs/el_env111/lib/python3.6/multiprocessing/popen_fork.py", line 73, in _launch
    code = process_obj._bootstrap()
  File "/gpfs/ysm/project/rtaylor/vs428/conda_envs/el_env111/lib/python3.6/multiprocessing/process.py", line 258, in _bootstrap
    self.run()
  File "/gpfs/ysm/home/vs428/Documents/luke/luke/pretraining/batch_generator.py", line 126, in run
    for item in self._pretraining_dataset.create_iterator(**self._dataset_kwargs):
  File "/gpfs/ysm/home/vs428/Documents/luke/luke/pretraining/medmentions_dataset.py", line 135, in create_iterator
    it = it.get_next()
  File "/gpfs/ysm/project/rtaylor/vs428/conda_envs/el_env111/lib/python3.6/site-packages/tensorflow_core/python/data/ops/iterator_ops.py", line 426, in get_next
    name=name)
  File "/gpfs/ysm/project/rtaylor/vs428/conda_envs/el_env111/lib/python3.6/site-packages/tensorflow_core/python/ops/gen_dataset_ops.py", line 2518, in iterator_get_next
    output_shapes=output_shapes, name=name)
  File "/gpfs/ysm/project/rtaylor/vs428/conda_envs/el_env111/lib/python3.6/site-packages/tensorflow_core/python/framework/op_def_library.py", line 794, in _apply_op_helper
    op_def=op_def)
  File "/gpfs/ysm/project/rtaylor/vs428/conda_envs/el_env111/lib/python3.6/site-packages/tensorflow_core/python/util/deprecation.py", line 507, in new_func
    return func(*args, **kwargs)
  File "/gpfs/ysm/project/rtaylor/vs428/conda_envs/el_env111/lib/python3.6/site-packages/tensorflow_core/python/framework/ops.py", line 3357, in create_op
    attrs, op_def, compute_device)
  File "/gpfs/ysm/project/rtaylor/vs428/conda_envs/el_env111/lib/python3.6/site-packages/tensorflow_core/python/framework/ops.py", line 3426, in _create_op_internal
    op_def=op_def)
  File "/gpfs/ysm/project/rtaylor/vs428/conda_envs/el_env111/lib/python3.6/site-packages/tensorflow_core/python/framework/ops.py", line 1748, in __init__
    self._traceback = tf_stack.extract_stack()

Traceback (most recent call last):
  File "/gpfs/ysm/home/vs428/Documents/luke/luke/pretraining/batch_generator.py", line 61, in generate_batches
    yield output_queue.get(True, 1)
  File "/gpfs/ysm/project/rtaylor/vs428/conda_envs/el_env111/lib/python3.6/multiprocessing/queues.py", line 105, in get
    raise Empty
queue.Empty

During handling of the above exception, another exception occurred:

Traceback (most recent call last):
  File "cli.py", line 77, in <module>
    cli()
  File "/gpfs/ysm/project/rtaylor/vs428/conda_envs/el_env111/lib/python3.6/site-packages/click/core.py", line 829, in __call__
    return self.main(*args, **kwargs)
  File "/gpfs/ysm/project/rtaylor/vs428/conda_envs/el_env111/lib/python3.6/site-packages/click/core.py", line 782, in main
    rv = self.invoke(ctx)
  File "/gpfs/ysm/project/rtaylor/vs428/conda_envs/el_env111/lib/python3.6/site-packages/click/core.py", line 1259, in invoke
    return _process_result(sub_ctx.command.invoke(sub_ctx))
  File "/gpfs/ysm/project/rtaylor/vs428/conda_envs/el_env111/lib/python3.6/site-packages/click/core.py", line 1066, in invoke
    return ctx.invoke(self.callback, **ctx.params)
  File "/gpfs/ysm/project/rtaylor/vs428/conda_envs/el_env111/lib/python3.6/site-packages/click/core.py", line 610, in invoke
    return callback(*args, **kwargs)
  File "/gpfs/ysm/home/vs428/Documents/luke/luke/pretraining/train.py", line 81, in pretrain
    run_pretraining(Namespace(**kwargs))
  File "/gpfs/ysm/home/vs428/Documents/luke/luke/pretraining/train.py", line 350, in run_pretraining
    for batch in batch_generator.generate_batches():
  File "/gpfs/ysm/home/vs428/Documents/luke/luke/pretraining/batch_generator.py", line 65, in generate_batches
    raise RuntimeError("Worker exited unexpectedly")
RuntimeError: Worker exited unexpectedly
  0%|          | 0/89 [01:12<?, ?it/s]Ran Pretraining
